Traceback (most recent call last):
  File "/Users/rolandmitric/anaconda3/lib/python3.10/site-packages/jupyter_cache/executors/utils.py", line 58, in single_nb_execution
    executenb(
  File "/Users/rolandmitric/anaconda3/lib/python3.10/site-packages/nbclient/client.py", line 1204, in execute
    return NotebookClient(nb=nb, resources=resources, km=km, **kwargs).execute()
  File "/Users/rolandmitric/anaconda3/lib/python3.10/site-packages/nbclient/util.py", line 84, in wrapped
    return just_run(coro(*args, **kwargs))
  File "/Users/rolandmitric/anaconda3/lib/python3.10/site-packages/nbclient/util.py", line 62, in just_run
    return loop.run_until_complete(coro)
  File "/Users/rolandmitric/anaconda3/lib/python3.10/asyncio/base_events.py", line 649, in run_until_complete
    return future.result()
  File "/Users/rolandmitric/anaconda3/lib/python3.10/site-packages/nbclient/client.py", line 663, in async_execute
    await self.async_execute_cell(
  File "/Users/rolandmitric/anaconda3/lib/python3.10/site-packages/nbclient/client.py", line 965, in async_execute_cell
    await self._check_raise_for_error(cell, cell_index, exec_reply)
  File "/Users/rolandmitric/anaconda3/lib/python3.10/site-packages/nbclient/client.py", line 862, in _check_raise_for_error
    raise CellExecutionError.from_cell_and_msg(cell, exec_reply_content)
nbclient.exceptions.CellExecutionError: An error occurred while executing the following cell:
------------------
beta_opt = solve(diff(E_psi, beta), beta)
beta_opt = simplify(beta_opt[0])
psi_opt = psi.subs({beta: beta_opt })
beta_opt
------------------

[0;31m---------------------------------------------------------------------------[0m
[0;31mNameError[0m                                 Traceback (most recent call last)
Cell [0;32mIn[7], line 1[0m
[0;32m----> 1[0m beta_opt [38;5;241m=[39m [43msolve[49m(diff(E_psi, beta), beta)
[1;32m      2[0m beta_opt [38;5;241m=[39m simplify(beta_opt[[38;5;241m0[39m])
[1;32m      3[0m psi_opt [38;5;241m=[39m psi[38;5;241m.[39msubs({beta: beta_opt })

[0;31mNameError[0m: name 'solve' is not defined
NameError: name 'solve' is not defined

